

import second_err;


can foo;