

import second_err;


def foo;